  0%|                              | 0/8812 [01:34<?, ?it/s]
Exception in thread Thread-4 (_pin_memory_loop):
Traceback (most recent call last):
  File "/usr/lib/python3.10/threading.py", line 1016, in _bootstrap_inner
    self.run()
  File "/usr/lib/python3.10/threading.py", line 953, in run
    self._target(*self._args, **self._kwargs)
  File "/home/wg25r/.local/lib/python3.10/site-packages/torch/utils/data/_utils/pin_memory.py", line 55, in _pin_memory_loop
    do_one_step()
  File "/home/wg25r/.local/lib/python3.10/site-packages/torch/utils/data/_utils/pin_memory.py", line 32, in do_one_step
    r = in_queue.get(timeout=MP_STATUS_CHECK_INTERVAL)
  File "/usr/lib/python3.10/multiprocessing/queues.py", line 122, in get
    return _ForkingPickler.loads(res)
  File "/home/wg25r/.local/lib/python3.10/site-packages/torch/multiprocessing/reductions.py", line 496, in rebuild_storage_fd
    fd = df.detach()
  File "/usr/lib/python3.10/multiprocessing/resource_sharer.py", line 57, in detach
    with _resource_sharer.get_connection(self._id) as conn:
  File "/usr/lib/python3.10/multiprocessing/resource_sharer.py", line 86, in get_connection
    c = Client(address, authkey=process.current_process().authkey)
  File "/usr/lib/python3.10/multiprocessing/connection.py", line 502, in Client
    c = SocketClient(address)
  File "/usr/lib/python3.10/multiprocessing/connection.py", line 630, in SocketClient
    s.connect(address)
ConnectionRefusedError: [Errno 111] Connection refused
